Workbook

Sheet 0. Hướng dẫn
A1: PHẢN HỒI YÊU CẦU CỦA KHỐI CNTT — 03 TRỢ LÝ AI
A2: Hồ sơ tài liệu cần cung cấp để CNTT đánh giá yêu cầu, xây dựng giải pháp kỹ thuật và xác định effort.
A4: CÁCH DÙNG FILE NÀY
A5: Sheet 1 – 3 | B5: Mỗi trợ lý một sheet, liệt kê đầy đủ các hạng mục tài liệu CNTT yêu cầu, chia theo 4 nhóm.
A6: Cột đã điền sẵn | B6: Cột D–G do đội dự án điền: trạng thái hiện tại, nội dung đã có, nguồn tài liệu, và phần còn thiếu.
A7: Cột cần anh/chị điền | B7: Cột H, I, J — tô màu VÀNG. Đây là phần để trống chờ bổ sung.
A8: Sheet 4 | B8: Bốn con số đang vênh giữa tài liệu gốc và bộ module — cần chốt trước khi đưa vào tiêu chí nghiệm thu.
A9: Sheet 5 | B9: Danh mục tài liệu nguồn hiện có kèm đường dẫn.
A10: Sheet 6 | B10: Danh sách việc cần làm, xếp theo thứ tự ưu tiên.
A11: Sheet 7 | B11: Bảng tổng hợp — tự động tính từ sheet 1–3, không cần điền tay.
A13: QUY ƯỚC MÀU VÀ TRẠNG THÁI
A14: Ô màu vàng | B14: Anh/chị điền vào đây.
A15: Ô màu kem | B15: Đội dự án đã điền — đọc để tham khảo, sửa nếu thấy chưa đúng.
A16: Đã có | B16: Đã có tài liệu, dùng được ngay.
A17: Một phần | B17: Có một phần, còn thiếu — xem cột G.
A18: Chưa có | B18: Chưa có tài liệu nào, phải bổ sung từ đầu.
A20: VÍ DỤ MỘT DÒNG ĐÃ ĐIỀN ĐẦY ĐỦ
A21: Hạng mục | B21: Trạng thái | C21: Nội dung đã có | D21: Nguồn tài liệu | E21: Còn thiếu | F21: Nội dung bổ sung (ĐIỀN) | G21: Người phụ trách (ĐIỀN)
A22: Bộ tiêu chí chấm hội thoại | B22: Đã có | C22: Bảng 10 tiêu chí, chuẩn đạt ≥ 8/10 | D22: Playbook Trực Page T10, mục 6 | E22: Cần văn bản xác nhận đây là bản đã duyệt | F22: Đã duyệt tại cuộc họp 05/10, biên bản số 12/BB-TP | G22: Mrs Nghĩa
A24: BỐN ĐIỂM CẦN LƯU Ý TRƯỚC KHI ĐIỀN
A25: • Nhóm ① Tri thức hiện đã phủ gần đủ. Đây KHÔNG phải phần đang chặn tiến độ.
A26: • Nhóm ② Quy trình hiện trạng và quy trình đích gần như trống hoàn toàn. ĐÂY MỚI LÀ PHẦN CHẶN CNTT ước lượng effort.
A27: • Bộ tiêu chí đánh giá chất lượng AI chưa có cho cả ba trợ lý. Lưu ý phân biệt với tiêu chí chấm NHÂN VIÊN (đã có) — đây là tiêu chí chấm chính con AI.
A28: • Bộ mẫu vàng (gold set) có thể đã có sẵn trong file "Chấm điểm 100 mẫu" của Mrs Nghĩa — nên kiểm tra trước khi làm lại từ đầu.

Sheet 1. AI QC
A1: TRỢ LÝ / HỆ THỐNG AI QC
A2: Đọc hội thoại trực page và telesale → chấm điểm theo bộ tiêu chí → phân loại → phân rã lỗi theo nhân viên → đề xuất đào tạo. Đây là trợ lý DUY NHẤT trong ba cái không chạm nội dung gửi khách.
A4: STT | B4: Nhóm | C4: Hạng mục cần cung cấp | D4: Trạng thái | E4: Nội dung đã có | F4: Nguồn tài liệu | G4: Còn thiếu — cần bổ sung | H4: NỘI DUNG BỔ SUNG | I4: NGƯỜI PHỤ TRÁCH | J4: DEADLINE
A5: 1 | B5: ① Tri thức + tiêu chí đánh giá AI | C5: Bộ tiêu chí chấm hội thoại (rubric) | D5: Đã có | E5: Bảng 10 tiêu chí, chuẩn đạt ≥ 8/10. Tiêu chí ⑨ "không dùng từ cấm" vi phạm là toàn hội thoại 0 điểm, bất kể 9 tiêu chí kia. | F5: Playbook Trực Page T10 · K8 §6 | G5: Cần văn bản xác nhận đây là bản ĐÃ DUYỆT để dùng đánh giá nhân sự.
A6: 2 | B6: ① Tri thức + tiêu chí đánh giá AI | C6: Danh sách từ cấm | D6: Đã có | E6: cam kết 100% · tốt nhất · không đau · an toàn tuyệt đối | F6: Playbook T10 · K8 §2 | G6: Xác nhận danh sách đã đầy đủ, có cần bổ sung từ nào không.
A7: 3 | B7: ① Tri thức + tiêu chí đánh giá AI | C7: Khung hội thoại chuẩn 5 bước B1–B5 | D7: Đã có | E7: B1 Mở · B2 Khám phá (thu đủ 3 thông tin) · B3 Tạo tin cậy · B4 Xin số có lý do · B5 Xác nhận tên Telesale, số gọi, giờ gọi. | F7: Tab "Kịch bản tiêu chuẩn" · K8 §2 | G7: Phân biệt page Bệnh viện và page Local chưa được đưa vào tiêu chí chấm.
A8: 4 | B8: ① Tri thức + tiêu chí đánh giá AI | C8: Bộ lỗi cấm và quy tắc tư vấn | D8: Đã có | E8: 8 lỗi cấm + 8 quy tắc vàng + luồng 7 bước hội thoại chuẩn. | F8: Tab "2. Thúc đẩy Chuyển đổi" · K5
A9: 5 | B9: ① Tri thức + tiêu chí đánh giá AI | C9: Taxonomy trạng thái L1–L6 | D9: Đã có | E9: 16 mã trạng thái, dùng để gán trạng thái cuối hội thoại. | F9: Tab "Vận hành xử lý dữ liệu" · K6 §2
A10: 6 | B10: ① Tri thức + tiêu chí đánh giá AI | C10: Phiếu bàn giao 12 trường | D10: Đã có | E10: Dùng để chấm tiêu chí ⑧ "đã lập phiếu bàn giao đủ trường". | F10: Playbook T10 · K8 §4
A11: 7 | B11: ① Tri thức + tiêu chí đánh giá AI | C11: Nguồn dữ liệu hội thoại và định dạng | D11: Chưa có | G11: Hội thoại lấy từ đâu (Caresoft?), xuất dạng gì. QUAN TRỌNG: có DẤU THỜI GIAN từng tin nhắn không — tiêu chí ① đo "phản hồi trong 2 phút", không có timestamp thì tiêu chí đó không chấm được.
A12: 8 | B12: ① Tri thức + tiêu chí đánh giá AI | C12: BỘ TIÊU CHÍ ĐÁNH GIÁ CHẤT LƯỢNG AI | D12: Chưa có | E12: Khung đề xuất: khớp điểm với QC người lệch ≤ 1 điểm ở ≥ 90% hội thoại · bắt đúng từ cấm 100% · chấm oan ≤ 5% · gán đúng mã trạng thái ≥ 90% · trích dẫn bằng chứng 100% · chấm lại cùng hội thoại lệch ≤ 1 điểm. | F12: Khung do đội dự án đề xuất — chưa được duyệt | G12: Kangnam chốt ngưỡng chính thức. LƯU Ý: đây là tiêu chí chấm CON AI, khác với tiêu chí chấm NHÂN VIÊN ở các dòng trên.
A13: 9 | B13: ① Tri thức + tiêu chí đánh giá AI | C13: Bộ mẫu vàng (gold set) | D13: Một phần | E13: Kế hoạch công việc có đầu việc "Audit kịch bản tư vấn nhân viên — 100 mẫu", output là "File chấm điểm 100 mẫu + bảng tổng hợp lỗi", giao Mrs Nghĩa. | F13: Tab "Trang tính8" | G13: Xác nhận file đã hoàn thành chưa. Nếu có thì xin file và xác nhận đây là bản đã duyệt — KHÔNG cần làm lại từ đầu.
A14: 10 | B14: ② Quy trình AS-IS / TO-BE | C14: Quy trình QC hiện trạng (AS-IS) | D14: Chưa có | G14: Hiện ai làm QC, mấy người, chấm theo rubric nào. Phủ bao nhiêu % hội thoại mỗi ngày, chọn mẫu thế nào. Mất bao lâu chấm một hội thoại. Bao lâu từ lúc hội thoại xảy ra đến khi nhân viên nhận phản hồi. Kết quả lưu ở đâu, dùng vào việc gì. Nhân viên có quyền khiếu nại không, ai xử lý.
A15: 11 | B15: ② Quy trình AS-IS / TO-BE | C15: Quy trình đích có AI (TO-BE) | D15: Chưa có | G15: AI chấm 100% hội thoại hay chỉ sàng lọc. QC người chuyển sang phúc tra mẫu hay vẫn chấm như cũ. Ngưỡng nào thì tự động đẩy lên người xem lại.
A16: 12 | B16: ② Quy trình AS-IS / TO-BE | C16: Điểm AI có dùng đánh giá nhân sự chính thức không | D16: Chưa có | G16: QUYẾT ĐỊNH QUAN TRỌNG — ảnh hưởng trực tiếp tới mức chính xác bắt buộc và quy trình khiếu nại. Cần chốt sớm.
A17: 13 | B17: ② Quy trình AS-IS / TO-BE | C17: Điểm tích hợp hệ thống | D17: Chưa có | G17: AI đọc hội thoại qua API hay qua file xuất định kỳ. Có ghi ngược kết quả vào Caresoft không, bằng quyền gì.
A18: 14 | B18: ② Quy trình AS-IS / TO-BE | C18: Trường dữ liệu và enum | D18: Chưa có | G18: Danh sách trường của bản ghi chấm điểm, kiểu dữ liệu, giá trị hợp lệ.
A19: 15 | B19: ② Quy trình AS-IS / TO-BE | C19: Sự kiện cần ghi log | D19: Chưa có | G19: Để tính được các chỉ số ở nhóm ④. Thiếu sự kiện nào thì chỉ số tương ứng không tính được.
A20: 16 | B20: ② Quy trình AS-IS / TO-BE | C20: Xử lý ngoại lệ | D20: Chưa có | G20: AI không chắc chắn thì sao. Dữ liệu thiếu dấu thời gian thì sao. Hệ thống lỗi thì quay về quy trình tay thế nào.
A21: 17 | B21: ③ Đối tượng sử dụng | C21: Danh sách nhân sự trực page | D21: Một phần | E21: Có danh sách chia nhóm A/B/C/D kèm mentor và điểm 3 khâu phễu. | F21: Playbook T10 · K8 §1 | G21: Chốt số lượng (tài liệu gốc ghi 15, bộ module ghi 17). Bổ sung ca làm việc và khối lượng xử lý mỗi ca.
A22: 18 | B22: ③ Đối tượng sử dụng | C22: Vai trò trong quy trình QC | D22: Chưa có | G22: Ai chấm, ai phúc tra, ai xử lý khiếu nại, ai nhận báo cáo đào tạo — kèm số lượng người từng vai trò.
A23: 19 | B23: ③ Đối tượng sử dụng | C23: Phân quyền | D23: Chưa có | G23: Vai trò nào xem được gì, sửa được gì, duyệt được gì.
A24: 20 | B24: ③ Đối tượng sử dụng | C24: Quy định về dữ liệu nhân sự | D24: Chưa có | G24: Ai được xem đánh giá hiệu suất có tên. Lưu ở đâu, giữ bao lâu. Ràng buộc không để lọt vào nội dung gửi khách.
A25: 21 | B25: ④ Mục tiêu & hiệu quả | C25: Baseline — điểm chấm hội thoại hiện tại | D25: Chưa có | G25: Nằm trong file chấm 100 mẫu nếu file đó đã làm xong.
A26: 22 | B26: ④ Mục tiêu & hiệu quả | C26: Baseline — tỷ lệ hội thoại được QC | D26: Chưa có | G26: Hiện bao nhiêu % hội thoại mỗi ngày được chấm.
A27: 23 | B27: ④ Mục tiêu & hiệu quả | C27: Baseline — thời gian chấm và thời gian phản hồi | D27: Chưa có | G27: Số phút cho một hội thoại. Số giờ từ lúc hội thoại đến lúc nhân viên nhận phản hồi.
A28: 24 | B28: ④ Mục tiêu & hiệu quả | C28: Mục tiêu | D28: Đã có | E28: Điểm chấm hội thoại ≥ 8/10. | F28: Playbook T10 · K8 §8 | G28: Bổ sung mục tiêu về độ phủ QC và thời gian phản hồi.
A29: 25 | B29: ④ Mục tiêu & hiệu quả | C29: Quy đổi hiệu quả | D29: Chưa có | G29: Người-giờ tiết kiệm được mỗi tháng. Giá trị quy đổi — cần để báo cáo duyệt ngân sách.
A30: 26 | B30: ④ Mục tiêu & hiệu quả | C30: Điểm ưu tiên triển khai | D30: Một phần | E30: Đề xuất ƯU TIÊN 1. Lý do: không chạm nội dung gửi khách nên rủi ro thấp nhất · tri thức đã chốt, dùng được ngay · tạo ra dữ liệu đo lường cho cả hệ thống, thứ mà hai trợ lý kia đang thiếu. | F30: Đề xuất của đội dự án | G30: Kangnam và CNTT xác nhận.
C32: Tổng số hạng mục | D32: =COUNTA(C5:C30)
C33: Đã bổ sung (số ô cột H đã điền) | D33: =COUNTA(H5:H30)
C34: Còn lại chưa bổ sung | D34: =D32-D33
C36: Ghi chú: cột D nhận 3 giá trị — Đã có / Một phần / Chưa có. Cập nhật lại cột D khi đã bổ sung xong tài liệu.

Sheet 2. AI Nhắc lịch TeleSale
A1: TRỢ LÝ / HỆ THỐNG AI NHẮC LỊCH VÀ TẠO NỘI DUNG CHĂM SÓC CHO CÁN BỘ TELESALE
A2: Từ danh sách khách + trạng thái + mốc gần nhất → sinh lịch "nhắc ai / khi nào / kênh gì" kèm nội dung gợi ý để cán bộ duyệt rồi gửi. Đây là trợ lý SINH NỘI DUNG THẬT SỰ ĐI TỚI KHÁCH — rủi ro cao nhất trong ba cái.
A4: STT | B4: Nhóm | C4: Hạng mục cần cung cấp | D4: Trạng thái | E4: Nội dung đã có | F4: Nguồn tài liệu | G4: Còn thiếu — cần bổ sung | H4: NỘI DUNG BỔ SUNG | I4: NGƯỜI PHỤ TRÁCH | J4: DEADLINE
A5: 1 | B5: ① Tri thức + tiêu chí đánh giá AI | C5: Chuỗi chăm sóc sau xin số | D5: Đã có | E5: T+0 (≤ 2 phút) → T+30 phút → T+2h → T+24h → T+72h → T+7 ngày là lần chạm cuối. | F5: Playbook T10 · K8 §5
A6: 2 | B6: ① Tri thức + tiêu chí đánh giá AI | C6: Nhịp theo dõi khách chưa booking | D6: Đã có | E6: D+3 → D+7 → D+15. | F6: Tab "Vận hành xử lý dữ liệu" · K6 §2
A7: 3 | B7: ① Tri thức + tiêu chí đánh giá AI | C7: Nhịp nuôi dưỡng bằng tài liệu | D7: Một phần | E7: N+1 hỏi thăm lại → N+3 gửi profile bác sĩ → N+5 video quy trình → N+7 video hành trình khách thật. | F7: Tab "2. Thúc đẩy Chuyển đổi" · K5 §6 | G7: Thiếu ĐƯỜNG DẪN tài liệu thực tế. Cần link còn sống và đã được duyệt, cho từng dịch vụ.
A8: 4 | B8: ① Tri thức + tiêu chí đánh giá AI | C8: Trần số lần nhắn | D8: Đã có | E8: Tối đa 6 lần trong 7 ngày. Khách từ chối là dừng ngay. | F8: Playbook T10 · K8 §5 | G8: Cần cài thành CHẶN CỨNG ở tầng hệ thống, không phó mặc cho AI tự nhớ.
A9: 5 | B9: ① Tri thức + tiêu chí đánh giá AI | C9: Điều kiện thoát | D9: Đã có | E9: Booking · từ chối dứt khoát · hết cửa sổ 24h Messenger · quá 30 ngày không tiến triển. | F9: Tab "Vận hành xử lý dữ liệu" · K6 §5 | G9: Tín hiệu "khách từ chối" nhận biết bằng cách nào — cần định nghĩa máy đọc được.
A10: 6 | B10: ① Tri thức + tiêu chí đánh giá AI | C10: Vòng phản hồi Telesale → trực page | D10: Đã có | E10: 4 trạng thái kèm thời hạn cập nhật và hành động kế tiếp của trực page. | F10: Playbook T10 · K8 §4
A11: 7 | B11: ① Tri thức + tiêu chí đánh giá AI | C11: Bank kịch bản nhắc lịch | D11: Một phần | E11: Chuỗi gọi nhỡ KB1–KB6 · báo trước khi gọi 15 phút · nuôi dưỡng qua Zalo. | F11: Tab "2. Thúc đẩy Chuyển đổi" · K5 §7 | G11: Mỗi nhóm thiết kế 16 slot kịch bản nhưng mới điền một phần. Cần bổ sung nội dung cho các slot còn trống.
A12: 8 | B12: ① Tri thức + tiêu chí đánh giá AI | C12: Kịch bản chiến dịch tháng | D12: Đã có | E12: Kịch bản tháng 10 theo 3 nhóm khách (chưa có số · có số gọi không nghe · đã gọi chưa booking). | F12: Tab "3. Thúc đẩy Kịch bản CT Tháng" · K7 | G12: Cần quy trình thay file mỗi tháng, người chịu trách nhiệm, và cách phát hiện khi thay sót.
A13: 9 | B13: ① Tri thức + tiêu chí đánh giá AI | C13: Phác đồ hậu phẫu từng dịch vụ | D13: Chưa có | G13: CHẶN CỨNG toàn bộ phần chăm sóc sau dịch vụ. Cần mốc tái khám, cắt chỉ, kiêng cữ theo từng dịch vụ — phải do bộ phận chuyên môn y khoa cung cấp.
A14: 10 | B14: ① Tri thức + tiêu chí đánh giá AI | C14: Danh sách bác sĩ được duyệt quảng bá | D14: Chưa có | G14: Chỉ được nhắc tên bác sĩ trong danh sách này. Kèm chứng chỉ hành nghề còn hiệu lực của từng người.
A15: 11 | B15: ① Tri thức + tiêu chí đánh giá AI | C15: Phân biệt page Bệnh viện và page Local | D15: Một phần | E15: Tài liệu có ghi nhận 2 loại page với giọng khác nhau — page Local gần gũi hơn, nhấn "đẹp gần nhà". | F15: Tab "Kịch bản tiêu chuẩn" | G15: Chưa có bộ nội dung riêng cho page Local.
A16: 12 | B16: ① Tri thức + tiêu chí đánh giá AI | C16: BỘ TIÊU CHÍ ĐÁNH GIÁ CHẤT LƯỢNG AI | D16: Chưa có | E16: Khung đề xuất: 0 ca nhắc khách đã chạm điều kiện thoát · 0 ca vượt trần 6 lần/7 ngày · 0 ca dùng số liệu hết hạn · 0 ca có từ cấm · chọn đúng nhịp ≥ 95% · không trùng nội dung giữa 2 lần chạm ≥ 90% · 0 ca sót nhịp · tỷ lệ cán bộ duyệt "dùng được luôn" ≥ 70%. | F16: Khung do đội dự án đề xuất — chưa được duyệt | G16: Kangnam chốt ngưỡng. Bốn tiêu chí đầu là NGƯỠNG TUYỆT ĐỐI, nên cài thành chặn cứng ở hệ thống chứ không phải chỉ tiêu phấn đấu.
A17: 13 | B17: ② Quy trình AS-IS / TO-BE | C17: Quy trình nhắc lịch và chăm sóc hiện trạng (AS-IS) | D17: Chưa có | G17: Telesale theo dõi lịch nhắc bằng gì (phần mềm / Excel / trí nhớ). Mỗi người ôm bao nhiêu khách cùng lúc. Mỗi ngày nhắc được bao nhiêu. Nội dung nhắn lấy từ đâu. Mất bao lâu soạn một tin cá nhân hoá. Ai kiểm soát việc nhắn quá nhiều.
A18: 14 | B18: ② Quy trình AS-IS / TO-BE | C18: Tỷ lệ sót nhịp hiện tại | D18: Chưa có | G18: Có đo được không. Nếu chưa đo được thì phải đo trước khi triển khai.
A19: 15 | B19: ② Quy trình AS-IS / TO-BE | C19: Quy trình đích có AI (TO-BE) | D19: Chưa có | G19: Sinh danh sách nhắc theo CA hay THỜI GIAN THỰC — khác nhau rất nhiều về chi phí tích hợp. Cán bộ duyệt từng tin hay theo lô. Nội dung đã duyệt có ghi ngược vào phần mềm không hay cán bộ tự dán.
A20: 16 | B20: ② Quy trình AS-IS / TO-BE | C20: Điểm tích hợp hệ thống | D20: Chưa có | G20: Đọc danh sách khách và lịch sử chạm từ đâu. Có ghi lại lần chạm không, ghi vào đâu.
A21: 17 | B21: ② Quy trình AS-IS / TO-BE | C21: Trường dữ liệu và enum | D21: Chưa có | G21: Trường theo dõi số lần chạm, mốc gần nhất, trạng thái thoát, kênh đã dùng.
A22: 18 | B22: ② Quy trình AS-IS / TO-BE | C22: Sự kiện cần ghi log | D22: Chưa có | G22: Để đếm được số lần chạm và tính được tỷ lệ sót nhịp.
A23: 19 | B23: ② Quy trình AS-IS / TO-BE | C23: Xử lý ngoại lệ | D23: Chưa có | G23: Dữ liệu chiến dịch tháng chưa cập nhật: hệ thống DỪNG sinh nội dung có số, hay vẫn sinh và gắn cảnh báo.
A24: 20 | B24: ③ Đối tượng sử dụng | C24: Danh sách cán bộ TeleSale | D24: Chưa có | G24: Bao nhiêu người, ca làm việc, khối lượng xử lý mỗi ca.
A25: 21 | B25: ③ Đối tượng sử dụng | C25: Vai trò trong quy trình | D25: Một phần | E25: Khung đề xuất: cán bộ TeleSale (người dùng chính) · nhân viên trực page · trưởng TeleSale · CSKH hậu phẫu · Marketing · Pháp chế · CNTT. | F25: Đề xuất của đội dự án | G25: Xác nhận và bổ sung số lượng từng vai trò.
A26: 22 | B26: ③ Đối tượng sử dụng | C26: Người chịu trách nhiệm cập nhật dữ liệu chiến dịch tháng | D26: Chưa có | G26: MẮT XÍCH DỄ ĐỨT NHẤT. Quên thay file là gửi khách ưu đãi đã hết hạn. Cần tên người cụ thể và người kiểm tra lại.
A27: 23 | B27: ③ Đối tượng sử dụng | C27: Phân quyền | D27: Chưa có | G27: Ai xem được khách của ai. Ai duyệt nội dung. Ai bấm dừng khi khách từ chối.
A28: 24 | B28: ④ Mục tiêu & hiệu quả | C28: Baseline — Kết nối / SĐT | D28: Đã có | E28: 72% | F28: Tab "Năng lực & đào tạo" | G28: Mục tiêu ghi 80% trong tài liệu gốc nhưng 78% trong bộ module — CẦN CHỐT.
A29: 25 | B29: ④ Mục tiêu & hiệu quả | C29: Baseline — Booking / Kết nối | D29: Đã có | E29: 45% | F29: Tab "Năng lực & đào tạo" | G29: Mục tiêu ghi 51% trong tài liệu gốc nhưng 50% trong bộ module — CẦN CHỐT.
A30: 26 | B30: ④ Mục tiêu & hiệu quả | C30: Baseline — tỷ lệ sót nhịp | D30: Chưa có
A31: 27 | B31: ④ Mục tiêu & hiệu quả | C31: Baseline — thời gian soạn một tin chăm sóc | D31: Chưa có
A32: 28 | B32: ④ Mục tiêu & hiệu quả | C32: Baseline — tỷ lệ tái khám đúng hẹn | D32: Chưa có | G32: Chỉ đo được khi đã có phác đồ hậu phẫu.
A33: 29 | B33: ④ Mục tiêu & hiệu quả | C33: Baseline — tỷ lệ khách phàn nàn bị làm phiền | D33: Chưa có | G33: Cần theo dõi để đảm bảo không tăng sau khi áp dụng.
A34: 30 | B34: ④ Mục tiêu & hiệu quả | C34: Quy đổi hiệu quả | D34: Chưa có | G34: Người-giờ tiết kiệm. Số lead cứu được khỏi rơi ở khâu nuôi dưỡng — khâu đắt nhất vì chi phí lấy được số điện thoại đã trả rồi.
A35: 31 | B35: ④ Mục tiêu & hiệu quả | C35: Điểm ưu tiên triển khai | D35: Một phần | E35: Đề xuất ƯU TIÊN 3. Không phải vì ít giá trị — giá trị kinh doanh rất rõ — mà vì phụ thuộc nhiều thứ chưa có và sai sót thì chạm thẳng vào khách. ĐỀ XUẤT TÁCH 2 GIAI ĐOẠN: chăm sóc trước chốt làm trước, hậu phẫu làm sau khi có phác đồ. | F35: Đề xuất của đội dự án | G35: Kangnam và CNTT xác nhận.
C37: Tổng số hạng mục | D37: =COUNTA(C5:C35)
C38: Đã bổ sung (số ô cột H đã điền) | D38: =COUNTA(H5:H35)
C39: Còn lại chưa bổ sung | D39: =D37-D38
C41: Ghi chú: cột D nhận 3 giá trị — Đã có / Một phần / Chưa có. Cập nhật lại cột D khi đã bổ sung xong tài liệu.

Sheet 3. AI Lead Scoring
A1: TRỢ LÝ / HỆ THỐNG AI LEAD SCORING
A2: Chấm 2 luồng (hội thoại page + cuộc gọi) → phân loại HOT/WARM/COLD kèm tín hiệu dẫn chứng → phục vụ định tuyến và SLA gọi. Không chạm nội dung gửi khách, nhưng quyết định AI ĐƯỢC GỌI TRƯỚC và TRONG BAO LÂU.
A4: STT | B4: Nhóm | C4: Hạng mục cần cung cấp | D4: Trạng thái | E4: Nội dung đã có | F4: Nguồn tài liệu | G4: Còn thiếu — cần bổ sung | H4: NỘI DUNG BỔ SUNG | I4: NGƯỜI PHỤ TRÁCH | J4: DEADLINE
A5: 1 | B5: ① Tri thức + tiêu chí đánh giá AI | C5: Bộ 5 tín hiệu phân loại HOT / WARM / COLD | D5: Đã có | E5: ① nêu dịch vụ cụ thể ② thời gian dự kiến ≤ 14 ngày ③ hỏi lịch, bác sĩ, hoặc chi phí theo tình trạng của mình ④ gửi ảnh hoặc mô tả rõ tình trạng ⑤ đồng ý nhận cuộc gọi trong khung giờ cụ thể. HOT 4–5 điểm · WARM 2–3 · COLD 0–1. | F5: Playbook T10 · K8 §3
A6: 2 | B6: ① Tri thức + tiêu chí đánh giá AI | C6: Bảng SLA gọi theo khung giờ | D6: Đã có | E6: 4 khung giờ × 3 mức ưu tiên. Giờ hành chính: HOT ≤ 5 phút · WARM ≤ 30 phút · COLD nhắn Zalo ≤ 2h. | F6: Playbook T10 · K8 §4
A7: 3 | B7: ① Tri thức + tiêu chí đánh giá AI | C7: Ba bậc Telesale và luật định tuyến | D7: Đã có | E7: Bậc 1 nhận HOT dịch vụ phẫu thuật · bậc 2 nhận HOT dịch vụ khác và WARM phẫu thuật · bậc 3 nhận WARM còn lại và COLD. Trần tải 8 số HOT mỗi giờ mỗi người, vượt thì chuyển người cùng bậc. | F7: Playbook T10 · K8 §4
A8: 4 | B8: ① Tri thức + tiêu chí đánh giá AI | C8: Phiếu bàn giao 12 trường | D8: Đã có | E8: Họ tên · SĐT · Zalo · Dịch vụ · Tình trạng · Mong muốn · Mối lo chính · Thời gian dự kiến · Khung giờ tiện · Điểm phân loại · Link hội thoại · Tên trực page. | F8: Playbook T10 · K8 §4
A9: 5 | B9: ① Tri thức + tiêu chí đánh giá AI | C9: Taxonomy trạng thái L1–L6 | D9: Đã có | E9: 16 mã. LƯU Ý: trạng thái L và mức ưu tiên HOT/WARM/COLD là HAI TRỤC RIÊNG, không gộp. | F9: Tab "Vận hành xử lý dữ liệu" · K6 §2
A10: 6 | B10: ① Tri thức + tiêu chí đánh giá AI | C10: Bảng tín hiệu cộng / trừ điểm 2 luồng | D10: Một phần | E10: Có bảng đề xuất chấm Luồng 1 (hội thoại page) và Luồng 2 (cuộc gọi telesale). | F10: Template A3 trong bộ module | G10: Mới là bản đề xuất v1, chưa được duyệt. Cần chốt: dùng bộ 5 tín hiệu, hay bảng điểm chi tiết, hay cả hai.
A11: 7 | B11: ① Tri thức + tiêu chí đánh giá AI | C11: Luật chia dữ liệu theo trạng thái | D11: Một phần | E11: Mới có luật cho L1.1 (hệ thống tự phân bổ inbox mới, realtime trong ca trực 7–22h) và L2.1 (nhân sự online xử lý trong ngày, sau 1 ngày chia đều cho toàn bộ nhân sự đi làm). | F11: Tab "Vận hành xử lý dữ liệu" | G11: CÒN TRỐNG cho L2.3, L2.4, L5.x, L6.x. Hiện AI đang chạy bằng đề xuất mặc định chứ không phải luật chính thức.
A12: 8 | B12: ① Tri thức + tiêu chí đánh giá AI | C12: Định nghĩa đồng hồ SLA | D12: Chưa có | G12: Tính từ mốc nào, dừng khi nào, ai bấm giờ, cảnh báo sắp quá hạn bắn ở đâu. Không có cái này thì chỉ tiêu "HOT gọi đúng SLA ≥ 90%" không đo được.
A13: 9 | B13: ① Tri thức + tiêu chí đánh giá AI | C13: Danh sách bậc của từng Telesale | D13: Chưa có | G13: Ai bậc 1, ai bậc 2, ai bậc 3. Lịch ca làm việc từng người.
A14: 10 | B14: ① Tri thức + tiêu chí đánh giá AI | C14: Định dạng nhật ký cuộc gọi | D14: Chưa có | G14: Luồng 2 chấm từ đâu: bản ghi cuộc gọi, tóm tắt tay, hay trường nhập sẵn trên phần mềm.
A15: 11 | B15: ① Tri thức + tiêu chí đánh giá AI | C15: BỘ TIÊU CHÍ ĐÁNH GIÁ CHẤT LƯỢNG AI | D15: Chưa có | E15: Khung đề xuất: trùng mức với người chấm ≥ 90% · Booking/HOT ≥ 60% · Booking/WARM ≥ 35% · tỷ lệ HOT trên tổng lead ổn định (chống lạm phát HOT) · tỷ lệ bỏ sót khách nóng càng thấp càng tốt · có dẫn chứng tín hiệu 100% · không dùng thuộc tính nhạy cảm (sức khoẻ, tài chính cá nhân) · phiếu đủ trường ≥ 95%. | F15: Khung do đội dự án đề xuất — chưa được duyệt | G15: Kangnam chốt ngưỡng. LƯU Ý: chất lượng trợ lý này KHÔNG đo được ngay — phải chờ kết quả booking thực tế rồi đối chiếu ngược, nên hệ thống bắt buộc phải LƯU LẠI điểm đã chấm.
A16: 12 | B16: ① Tri thức + tiêu chí đánh giá AI | C16: Bộ mẫu vàng lead | D16: Chưa có | G16: Tập lead đã được người chấm và duyệt, kèm kết quả booking thực tế để đối chiếu.
A17: 13 | B17: ② Quy trình AS-IS / TO-BE | C17: Quy trình chia lead hiện trạng (AS-IS) | D17: Một phần | E17: Có một phần: L1.1 hệ thống tự động phân bổ inbox mới, realtime trong ca trực 7–22h; L2.1 nhân sự online chủ động xử lý trong ngày, sau 1 ngày lấy toàn bộ dữ liệu chia đều. | F17: Tab "Vận hành xử lý dữ liệu" | G17: Thiếu phần quan trọng nhất: lead ĐÃ CÓ SĐT được chia cho Telesale thế nào. Hiện có phân loại mức ưu tiên không, ai phân, dựa trên gì.
A18: 14 | B18: ② Quy trình AS-IS / TO-BE | C18: Thời gian từ có số đến gọi lần đầu (hiện tại) | D18: Chưa có | G18: Con số này chính là baseline của SLA.
A19: 15 | B19: ② Quy trình AS-IS / TO-BE | C19: Tỷ lệ phiếu bàn giao điền đủ trường (hiện tại) | D19: Chưa có | G19: Hiện phiếu có mấy trường, tỷ lệ điền đủ bao nhiêu.
A20: 16 | B20: ② Quy trình AS-IS / TO-BE | C20: Xử lý quá tải giờ cao điểm (hiện tại) | D20: Chưa có | G20: Giờ cao điểm tải bao nhiêu số mỗi giờ. Hiện xử lý quá tải thế nào.
A21: 17 | B21: ② Quy trình AS-IS / TO-BE | C21: Quy trình đích có AI (TO-BE) | D21: Chưa có | G21: AI chấm xong thì TỰ ĐỊNH TUYẾN hay chỉ ĐỀ XUẤT để điều phối viên bấm duyệt. Xử lý khi tất cả người cùng bậc đều quá tải: xếp hàng, hạ bậc, hay báo trưởng nhóm. Cảnh báo sắp quá hạn SLA hiện ra ở đâu, cho ai thấy.
A22: 18 | B22: ② Quy trình AS-IS / TO-BE | C22: Nguồn sự thật của trạng thái | D22: Chưa có | G22: QUYẾT ĐỊNH CHẶN CẢ BA TRỢ LÝ: người gán trạng thái hay máy gán. Gán lệch nhau thì ai thắng. Phải chốt trước tiên.
A23: 19 | B23: ② Quy trình AS-IS / TO-BE | C23: Điểm tích hợp hệ thống | D23: Chưa có | G23: Đọc hội thoại và nhật ký gọi từ đâu. Ghi điểm và phiếu bàn giao vào đâu, bằng quyền gì.
A24: 20 | B24: ② Quy trình AS-IS / TO-BE | C24: Trường dữ liệu và enum | D24: Một phần | E24: Yêu cầu đã biết: L-code và HOT/WARM/COLD phải là HAI CỘT RIÊNG, không gộp. | F24: Đề xuất của đội dự án | G24: Danh sách trường đầy đủ, kiểu dữ liệu, giá trị hợp lệ của từng enum.
A25: 21 | B25: ② Quy trình AS-IS / TO-BE | C25: Sự kiện cần ghi log | D25: Chưa có | G25: Bắt buộc lưu LỊCH SỬ CHẤM để sau này ghép với kết quả booking — đây là cách duy nhất đo được độ chính xác.
A26: 22 | B26: ② Quy trình AS-IS / TO-BE | C26: Xử lý ngoại lệ | D26: Chưa có | G26: AI không đủ tín hiệu để chấm thì sao. Thiếu trường bắt buộc thì có chấm không.
A27: 23 | B27: ③ Đối tượng sử dụng | C27: Danh sách Telesale theo bậc | D27: Chưa có | G27: Tên, bậc, ca làm việc, tải tối đa mỗi người.
A28: 24 | B28: ③ Đối tượng sử dụng | C28: Vai trò trong quy trình | D28: Một phần | E28: Khung đề xuất: nhân viên trực page (tạo lead, điền phiếu — chất lượng đầu vào phụ thuộc người này) · Telesale 3 bậc · điều phối / trưởng Telesale · bộ phận dữ liệu · lãnh đạo vận hành · CNTT. | F28: Đề xuất của đội dự án | G28: Xác nhận và bổ sung số lượng từng vai trò.
A29: 25 | B29: ③ Đối tượng sử dụng | C29: Phân quyền | D29: Chưa có | G29: Ai sửa được mức ưu tiên AI đã chấm, có bắt buộc ghi lý do không. Ai điều chuyển được lead.
A30: 26 | B30: ④ Mục tiêu & hiệu quả | C30: Baseline — Xin số | D30: Đã có | E30: 42% (mục tiêu 39% — đang vượt mục tiêu) | F30: Tab "Năng lực & đào tạo"
A31: 27 | B31: ④ Mục tiêu & hiệu quả | C31: Baseline — Kết nối / SĐT | D31: Đã có | E31: 72% — KHÂU HỔNG NẶNG NHẤT | F31: Tab "Năng lực & đào tạo" | G31: Mục tiêu 80% (tài liệu gốc) hay 78% (bộ module) — CẦN CHỐT.
A32: 28 | B32: ④ Mục tiêu & hiệu quả | C32: Baseline — Chuyển đổi tổng (inbox → booking) | D32: Đã có | E32: 13,7% | F32: Tab "Năng lực & đào tạo" | G32: Mục tiêu 16,5%.
A33: 29 | B33: ④ Mục tiêu & hiệu quả | C33: Baseline — HOT gọi đúng SLA | D33: Chưa có | G33: Chỉ đo được sau khi có định nghĩa đồng hồ SLA.
A34: 30 | B34: ④ Mục tiêu & hiệu quả | C34: Baseline — tỷ lệ phiếu đủ trường | D34: Chưa có
A35: 31 | B35: ④ Mục tiêu & hiệu quả | C35: Baseline — tỷ lệ HOT trên tổng lead | D35: Chưa có | G35: Cần để theo dõi rủi ro lạm phát HOT.
A36: 32 | B36: ④ Mục tiêu & hiệu quả | C36: Mục tiêu | D36: Đã có | E36: HOT gọi đúng SLA ≥ 90% · số được phân loại và có phiếu đủ ≥ 95% · Booking/HOT ≥ 60% · Booking/WARM ≥ 35%. | F36: Playbook T10 · K8 §8
A37: 33 | B37: ④ Mục tiêu & hiệu quả | C37: Quy đổi hiệu quả | D37: Chưa có | G37: Tác động trực tiếp nhất tới doanh thu. Cần quy đổi ra số lead chuyển đổi tăng thêm.
A38: 34 | B38: ④ Mục tiêu & hiệu quả | C38: Điểm ưu tiên triển khai | D38: Một phần | E38: Đề xuất ƯU TIÊN 2. Tri thức đã chốt, nhưng CHỈ PHÁT HUY khi đồng hồ SLA và luật định tuyến đã có — chấm điểm mà không ai gọi đúng giờ thì điểm số không tạo ra giá trị nào. | F38: Đề xuất của đội dự án | G38: Kangnam và CNTT xác nhận.
C40: Tổng số hạng mục | D40: =COUNTA(C5:C38)
C41: Đã bổ sung (số ô cột H đã điền) | D41: =COUNTA(H5:H38)
C42: Còn lại chưa bổ sung | D42: =D40-D41
...

Sheet 4. Số liệu cần chốt
A1: SỐ LIỆU ĐANG VÊNH GIỮA CÁC NGUỒN — CẦN CHỐT TRƯỚC
A2: Nhỏ, nhưng nếu đưa vào tiêu chí nghiệm thu mà hai bên cầm hai con số khác nhau thì đến lúc nghiệm thu mới phát sinh tranh cãi.
A4: STT | B4: Nội dung | C4: Tài liệu gốc ghi | D4: Bộ module ghi | E4: CHỐT DÙNG SỐ NÀO | F4: NGƯỜI QUYẾT | G4: NGÀY CHỐT
A5: 1 | B5: Mục tiêu tỷ lệ kết nối | C5: 80% | D5: ≥ 78%
A6: 2 | B6: Mục tiêu tỷ lệ chốt lịch sau kết nối | C6: 51% | D6: ≥ 50%
A7: 3 | B7: Nhịp chăm khách đang tư vấn chưa ra số | C7: Nhắn lại sau 3h, ngày 3 lần, liên tục trong 4 ngày | D7: Sau 1 ngày, trong vòng 7 ngày, lúc 9h và 15h
A8: 4 | B8: Số nhân sự trực page được đánh giá | C8: 15 người | D8: 17 người
B10: Bổ sung các số liệu khác nếu phát hiện thêm trong quá trình rà soát:
A11: 5
A12: 6
A13: 7
A14: 8

Sheet 5. Tài liệu nguồn
A1: DANH MỤC TÀI LIỆU NGUỒN HIỆN CÓ
A2: Hai tài liệu đầu là bản gốc. Bộ module là bản dẫn xuất đã cấu trúc hoá để nạp cho AI.
A4: STT | B4: Tên tài liệu | C4: Dạng | D4: Phủ được gì | E4: Đường dẫn / Vị trí | F4: TRẠNG THÁI DUYỆT | G4: GHI CHÚ
A5: 1 | B5: Playbook Trực Page Tháng 10 | C5: Văn bản | D5: Ma trận năng lực nhân sự · khung tư vấn 5 bước · phân loại HOT/WARM/COLD · bàn giao và SLA · chuỗi chăm sóc T+0→T+7 · bảng chấm 10 tiêu chí · kế hoạch đào tạo · KPI và rủi ro | E5: https://claude.ai/artifact/Y2kfjUUJ3z4tF54DPsbzwg
A6: 2 | B6: 1. Trực page — Tối ưu kịch bản tư vấn và chăm sóc sau xin số | C6: Bảng tính, 9 tab | D6: Kịch bản tiêu chuẩn · Năng lực & đào tạo (CÓ BASELINE) · Cài đặt KB lên hệ thống · Thúc đẩy chuyển đổi · Kịch bản chiến dịch tháng · Vận hành xử lý dữ liệu · Kế hoạch công việc kèm người và deadline · Danh sách page theo dịch vụ | E6: https://docs.google.com/spreadsheets/d/1-iNOSA4FIAfyRe1cWBzLdpY_U6C3mjrv3x_aQfbZ0SU
A7: 3 | B7: Bộ module tri thức K1–K8 + template A1–A4 | C7: Thư mục file .md | D7: Bản đã cấu trúc hoá từ hai tài liệu trên, dạng máy đọc được — nạp thẳng cho AI | E7: https://github.com/huudinh/Kangnam-Agent-Factory
A8: 4 | B8: Trang hướng dẫn Agent Factory Kangnam | C8: Trang web | D8: Hướng dẫn cài đặt, câu lệnh, QA cơ bản, và hồ sơ bàn giao CNTT (mục 7) | E8: https://claude.ai/artifact/PWmzQ3PkLfZ6yjnt8gm8K2
A9: 5 | B9: File chấm điểm 100 mẫu + bảng tổng hợp lỗi | C9: Chưa xác định | D9: NẾU ĐÃ HOÀN THÀNH: vừa là bộ mẫu vàng cho AI QC, vừa cho ra baseline điểm trung bình và bảng tần suất lỗi — một việc giải quyết hai hạng mục
B11: Lưu ý: tài liệu Playbook hiện không thuộc tài khoản của đội dự án, nên chưa rõ ai được sửa và bản nào là bản đã duyệt.

Sheet 6. Việc cần làm
A1: VIỆC CẦN LÀM ĐỂ TRẢ LỜI ĐỦ CHO CNTT
A2: Bốn việc đầu không cần viết dòng code nào và không phải chờ ai bên ngoài.
A4: STT | B4: Việc | C4: Vì sao cần | D4: Đầu ra mong đợi | E4: NGƯỜI PHỤ TRÁCH | F4: DEADLINE | G4: TRẠNG THÁI
A5: 1 | B5: Chốt 4 con số đang vênh | C5: Tránh tranh cãi lúc nghiệm thu nếu hai bên cầm hai con số khác nhau | D5: Sheet "4. Số liệu cần chốt" đã điền xong cột E
A6: 2 | B6: Xin file "Chấm điểm 100 mẫu" và xác nhận bản đã duyệt | C6: Nếu có rồi thì bộ mẫu vàng VÀ baseline của AI QC coi như xong — đỡ được hạng mục nặng nhất | D6: File + văn bản xác nhận đây là bản đã duyệt
A7: 3 | B7: Kiểm tra trạng thái đầu việc "Họp với CNTT làm công cụ QC" (hạn 8/10) | C7: Việc này đã có chủ và đã quá hạn — có thể đã bắt đầu rồi, tránh mở luồng yêu cầu trùng lặp | D7: Biên bản họp + yêu cầu kỹ thuật công cụ QC
A8: 4 | B8: Chốt nguồn sự thật của trạng thái (người gán hay máy gán) | C8: Cả ba trợ lý đều chạy trên trạng thái này. Không chốt thì mọi thứ sau phải làm lại | D8: Văn bản quy định + quy tắc xử lý khi hai bên gán lệch
A9: 5 | B9: Viết tài liệu nhóm ② và ③ cho AI QC trước | C9: Đây là phần đang chặn CNTT ước lượng effort. Làm xong một bộ mẫu rồi nhân sang hai trợ lý kia | D9: Tài liệu quy trình AS-IS / TO-BE + danh sách vai trò và phân quyền
A10: 6 | B10: Chốt ngưỡng cho bộ tiêu chí đánh giá chất lượng AI (cả 3 trợ lý) | C10: Khung đề xuất đã có sẵn trong sheet 1–3, chỉ cần Kangnam chốt con số | D10: Bảng tiêu chí đã duyệt, dùng làm căn cứ nghiệm thu
A11: 7 | B11: CNTT trả lời phần hạ tầng | C11: Quyết định phương án tích hợp có khả thi không | D11: AI chạy ở đâu, đọc dữ liệu Caresoft bằng cách nào, log lưu đâu, ràng buộc với dữ liệu định danh khách
A12: 8 | B12: Triển khai AI QC phạm vi hẹp, chạy song song với QC người | C12: Đối chiếu trước khi mở rộng — rủi ro thấp nhất trong ba trợ lý | D12: Báo cáo đối chiếu sau giai đoạn chạy thử

Sheet 7. Tổng hợp
A1: TỔNG HỢP MỨC ĐÁP ỨNG
A2: Bảng trên tự động tính từ sheet 1–3, không cần điền tay.
A4: Trợ lý AI | B4: Tổng hạng mục | C4: Đã có | D4: Một phần | E4: Chưa có | F4: Đã bổ sung
A5: 1. AI QC | B5: =COUNTA('1. AI QC'!$C$5:$C$30) | C5: =COUNTIF('1. AI QC'!$D$5:$D$30,"Đã có") | D5: =COUNTIF('1. AI QC'!$D$5:$D$30,"Một phần") | E5: =COUNTIF('1. AI QC'!$D$5:$D$30,"Chưa có") | F5: =COUNTA('1. AI QC'!$H$5:$H$30)
A6: 2. AI Nhắc lịch TeleSale | B6: =COUNTA('2. AI Nhắc lịch TeleSale'!$C$5:$C$35) | C6: =COUNTIF('2. AI Nhắc lịch TeleSale'!$D$5:$D$35,"Đã có") | D6: =COUNTIF('2. AI Nhắc lịch TeleSale'!$D$5:$D$35,"Một phần") | E6: =COUNTIF('2. AI Nhắc lịch TeleSale'!$D$5:$D$35,"Chưa có") | F6: =COUNTA('2. AI Nhắc lịch TeleSale'!$H$5:$H$35)
A7: 3. AI Lead Scoring | B7: =COUNTA('3. AI Lead Scoring'!$C$5:$C$38) | C7: =COUNTIF('3. AI Lead Scoring'!$D$5:$D$38,"Đã có") | D7: =COUNTIF('3. AI Lead Scoring'!$D$5:$D$38,"Một phần") | E7: =COUNTIF('3. AI Lead Scoring'!$D$5:$D$38,"Chưa có") | F7: =COUNTA('3. AI Lead Scoring'!$H$5:$H$38)
A8: TỔNG CỘNG | B8: =SUM(B5:B7) | C8: =SUM(C5:C7) | D8: =SUM(D5:D7) | E8: =SUM(E5:E7) | F8: =SUM(F5:F7)
A10: MA TRẬN ĐÁP ỨNG THEO NHÓM TÀI LIỆU
A11: Hạng mục CNTT yêu cầu | B11: AI QC | C11: AI Nhắc lịch TeleSale | D11: AI Lead Scoring
A12: ① Tri thức cho AI | B12: Gần đủ | C12: Một phần | D12: Gần đủ
A13: ① Bộ tiêu chí đánh giá chất lượng AI | B13: Chưa có | C13: Chưa có | D13: Chưa có
A14: ② Quy trình hiện trạng (AS-IS) | B14: Chưa có | C14: Chưa có | D14: Một phần nhỏ
A15: ② Quy trình đích có AI (TO-BE) | B15: Chưa có | C15: Chưa có | D15: Chưa có
A16: ③ Đối tượng sử dụng | B16: Một phần | C16: Chưa có | D16: Chưa có
A17: ④ Mục tiêu & hiệu quả | B17: Một phần | C17: Một phần | D17: Một phần
A19: KẾT LUẬN: nhóm ① đủ để CNTT HIỂU BÀI TOÁN. Nhưng để ƯỚC LƯỢNG EFFORT thì cần nhóm ② — quy trình, điểm tích hợp, trường dữ liệu, sự kiện log — và nhóm đó đang trống gần hoàn toàn. Với bộ tài liệu hiện tại, CHƯA ƯỚC LƯỢNG ĐƯỢC EFFORT cho bất kỳ trợ lý nào. Việc cần làm ngay không phải bổ sung thêm tri thức, mà là viết quy trình hiện trạng và chốt quy trình đích.
